Workbook

Sheet FY10 Totals
D1: Project Automation - FY 2010
B2: Test Cases | D2: Q1 | E2: Q2 | F2: Q3 | G2: Q4 | H2: Total Scripts | I2: % FY2010 Automation | J2: Total Project Automation | L2: Automation to Date
A3: Automation Type | B3: WinR | C3: New TC | D3: TS | E3: TS | F3: TS | G3: TS | H3: FY 2010 | J3: TC | K3: TS
A4: MAP - Pro/JCL | B4: ='FY2010 Coverage'!E25 -> 285 | C4: ='FY2010 Coverage'!F25 -> 0 | D4: ='FY2010 Coverage'!G25 -> 21 | E4: ='FY2010 Coverage'!H25 -> 0 | F4: ='FY2010 Coverage'!I25 -> 0 | G4: ='FY2010 Coverage'!J25 -> 0 | H4: ='FY2010 Coverage'!K25 -> 21 | I4: =H4/J4 -> 0.073684211 | J4: =SUM(B4:C4) -> 285 | K4: ='FY2010 Coverage'!L25 -> 253 | L4: =K4/J4 -> 0.8877193
A5: MAP - Info/Xe | B5: ='FY2010 Coverage'!E50 -> 173 | C5: ='FY2010 Coverage'!F50 -> 2 | D5: ='FY2010 Coverage'!G50 -> 4 | E5: ='FY2010 Coverage'!H50 -> 71 | F5: ='FY2010 Coverage'!I50 -> 0 | G5: ='FY2010 Coverage'!J50 -> 0 | H5: ='FY2010 Coverage'!K50 -> 75 | I5: =H5/J5 -> 0.42857143 | J5: =SUM(B5:C5) -> 175 | K5: =SUM(C5,D5,E5,F5) -> 77 | L5: =K5/J5 -> 0.44
A7: Totals | B7: =SUM(B4:B6) -> 458 | C7: =SUM(C4:C6) -> 2 | D7: =SUM(D4:D6) -> 25 | E7: =SUM(E4:E6) -> 71 | F7: =SUM(F4:F6) -> 0 | G7: =SUM(G4:G6) -> 0 | H7: =SUM(H4:H6) -> 96 | I7: =H7/J7 -> 0.20869565 | J7: =SUM(J4:J6) -> 460 | K7: =SUM(K4:K6) -> 330 | L7: =K7/J7 -> 0.7173913
A12: Totals for each Automation Developer
B13: Test Cases | D13: Q1 | E13: Q2 | F13: Q3 | G13: Q4 | H13: Total Scripts | I13: % FY2010 Automation | J13: Developer Totals | L13: Automation by Developer
A14: Developer | B14: WinR | C14: New TC | D14: TS | E14: TS | F14: TS | G14: TS | H14: FY 2010 | J14: TC | K14: TS
A15: Claudie | B15: ='FY2010 Coverage'!E58 -> 368 | C15: ='FY2010 Coverage'!F58 -> 1 | D15: ='FY2010 Coverage'!G58 -> 24 | E15: ='FY2010 Coverage'!H58 -> 62 | F15: ='FY2010 Coverage'!I58 -> 0 | G15: ='FY2010 Coverage'!J58 -> 0 | H15: ='FY2010 Coverage'!K58 -> 86 | I15: =H15/J15 -> 0.23306233 | J15: =SUM(B15:C15) -> 369 | K15: ='FY2010 Coverage'!L58 -> 318 | L15: =K15/J15 -> 0.86178862
A16: Lisa | B16: ='FY2010 Coverage'!E60 -> 90 | C16: ='FY2010 Coverage'!F62 -> 0 | D16: ='FY2010 Coverage'!G60 -> 1 | E16: ='FY2010 Coverage'!H60 -> 11 | F16: ='FY2010 Coverage'!I60 -> 0 | G16: ='FY2010 Coverage'!J60 -> 0 | H16: ='FY2010 Coverage'!K60 -> 10 | I16: =H16/J16 -> 0.11111111 | J16: =SUM(B16:C16) -> 90 | K16: ='FY2010 Coverage'!L60 -> 10 | L16: =K16/J16 -> 0.11111111
A17: Scott | B17: ='FY2010 Coverage'!E59 -> 0 | C17: ='FY2010 Coverage'!F61 -> 0 | D17: ='FY2010 Coverage'!G59 -> 0 | E17: ='FY2010 Coverage'!H59 -> 0 | F17: ='FY2010 Coverage'!I59 -> 0 | G17: ='FY2010 Coverage'!J59 -> 0 | H17: ='FY2010 Coverage'!K59 -> 0 | J17: =SUM(B17:C17) -> 0 | K17: ='FY2010 Coverage'!L59 -> 0
A18: Totals | B18: =SUM(B15:B16) -> 458 | C18: =SUM(C15:C16) -> 1 | D18: =SUM(D15:D16) -> 25 | E18: =SUM(E15:E16) -> 73 | F18: =SUM(F15:F16) -> 0 | G18: =SUM(G15:G16) -> 0 | H18: =SUM(H15:H16) -> 96 | I18: =H18/J18 -> 0.20915033 | J18: =SUM(J15:J16) -> 459 | K18: =SUM(K15:K17) -> 328 | L18: =K18/J18 -> 0.71459695

Sheet FY2010 Coverage
A1: Automation Type | B1: Product | C1: Area Covered | D1: Owner | E1: WinRunner Cases | F1: New Test Cases | G1: Scripts Q1 | H1: Scripts Q2 | I1: Scripts Q3 | J1: Scripts Q4 | K1: Scripts FY10 | L1: Total Scripts | M1: % complt
A2: MAP | B2: Pro/JCL | C2: Admin | D2: Claudie | E2: ='Coverage-Detail-ProJcl-2010'!A12 -> 7 | F2: ='Coverage-Detail-ProJcl-2010'!E12 -> 0 | G2: =COUNTIF('Coverage-Detail-ProJcl-2010'!H5:H11,"Q1") -> 0 | H2: =COUNTIF('Coverage-Detail-ProJcl-2010'!H5:H11,"Q2") -> 0 | I2: =COUNTIF('Coverage-Detail-ProJcl-2010'!H5:H11,"Q3") -> 0 | J2: =COUNTIF('Coverage-Detail-ProJcl-2010'!H5:H11,"Q4") -> 0 | K2: =SUM(G2:J2) -> 0 | L2: =COUNTIF('Coverage-Detail-ProJcl-2010'!D5:D11,"X") -> 6 | M2: =L2/E2*100 -> 85.714286
A3: MAP | B3: Pro/JCL | C3: Help | D3: Claudie | E3: =SUM('Coverage-Detail-ProJcl-2010'!A32,'Coverage-Detail-ProJcl-2010'!A21) -> 14 | F3: ='Coverage-Detail-ProJcl-2010'!E32 -> 0 | G3: =COUNTIF('Coverage-Detail-ProJcl-2010'!H15:H31,"Q1") -> 0 | H3: =COUNTIF('Coverage-Detail-ProJcl-2010'!H15:H31,"Q2") -> 0 | I3: =COUNTIF('Coverage-Detail-ProJcl-2010'!H15:H31,"Q3") -> 0 | J3: =COUNTIF('Coverage-Detail-ProJcl-2010'!H15:H31,"Q4") -> 0 | K3: =SUM(G3:J3) -> 0 | L3: =COUNTIF('Coverage-Detail-ProJcl-2010'!D15:D31,"X") -> 14 | M3: =L3/E3*100 -> 100
A4: MAP | B4: Pro/JCL | C4: JJ | D4: Claudie | E4: =SUM('Coverage-Detail-ProJcl-2010'!A52,'Coverage-Detail-ProJcl-2010'!A87) -> 50 | F4: ='Coverage-Detail-ProJcl-2010'!E87 -> 0 | G4: =COUNTIF('Coverage-Detail-ProJcl-2010'!H34:H86,"Q1") -> 1 | H4: =COUNTIF('Coverage-Detail-ProJcl-2010'!H34:H86,"Q2") -> 0 | I4: =COUNTIF('Coverage-Detail-ProJcl-2010'!H34:H86,"Q3") -> 0 | J4: =COUNTIF('Coverage-Detail-ProJcl-2010'!H34:H86,"Q4") -> 0 | K4: =SUM(G4:J4) -> 1 | L4: =COUNTIF('Coverage-Detail-ProJcl-2010'!D34:D86,"X") -> 49 | M4: =L4/E4*100 -> 98
A5: MAP | B5: Pro/JCL | C5: JJDirect | D5: Claudie | E5: ='Coverage-Detail-ProJcl-2010'!A105 -> 15 | F5: ='Coverage-Detail-ProJcl-2010'!E105 -> 0 | G5: =COUNTIF('Coverage-Detail-ProJcl-2010'!H90:H104,"Q1") -> 4 | H5: =COUNTIF('Coverage-Detail-ProJcl-2010'!H90:H104,"Q2") -> 0 | I5: =COUNTIF('Coverage-Detail-ProJcl-2010'!H90:H104,"Q3") -> 0 | J5: =COUNTIF('Coverage-Detail-ProJcl-2010'!H90:H104,"Q4") -> 0 | K5: =SUM(G5:J5) -> 4 | L5: =COUNTIF('Coverage-Detail-ProJcl-2010'!D90:D104,"X") -> 13 | M5: =L5/E5*100 -> 86.666667
A6: MAP | B6: Pro/JCL | C6: JJScan | D6: Claudie | E6: ='Coverage-Detail-ProJcl-2010'!A111 -> 3 | F6: ='Coverage-Detail-ProJcl-2010'!E111 -> 0 | G6: =COUNTIF('Coverage-Detail-ProJcl-2010'!H108:H110,"Q1") -> 1 | H6: =COUNTIF('Coverage-Detail-ProJcl-2010'!H108:H110,"Q2") -> 0 | I6: =COUNTIF('Coverage-Detail-ProJcl-2010'!H108:H110,"Q3") -> 0 | J6: =COUNTIF('Coverage-Detail-ProJcl-2010'!H108:H110,"Q4") -> 0 | K6: =SUM(G6:J6) -> 1 | L6: =COUNTIF('Coverage-Detail-ProJcl-2010'!D108:D110,"X") -> 3 | M6: =L6/E6*100 -> 100
A7: MAP | B7: Pro/JCL | C7: JMP | D7: Claudie | E7: ='Coverage-Detail-ProJcl-2010'!A138 -> 25 | F7: ='Coverage-Detail-ProJcl-2010'!E138 -> 0 | G7: =COUNTIF('Coverage-Detail-ProJcl-2010'!H113:H137,"Q1") -> 3 | H7: =COUNTIF('Coverage-Detail-ProJcl-2010'!H113:H137,"Q2") -> 0 | I7: =COUNTIF('Coverage-Detail-ProJcl-2010'!H113:H137,"Q3") -> 0 | J7: =COUNTIF('Coverage-Detail-ProJcl-2010'!H113:H137,"Q4") -> 0 | K7: =SUM(G7:J7) -> 3 | L7: =COUNTIF('Coverage-Detail-ProJcl-2010'!D113:D137,"X") -> 25 | M7: =L7/E7*100 -> 100
A8: MAP | B8: Pro/JCL | C8: MISC | D8: Claudie | E8: ='Coverage-Detail-ProJcl-2010'!A142 -> 7 | F8: ='Coverage-Detail-ProJcl-2010'!E142 -> 0 | G8: =COUNTIF('Coverage-Detail-ProJcl-2010'!H140:H141,"Q1") -> 0 | H8: =COUNTIF('Coverage-Detail-ProJcl-2010'!H140:H141,"Q2") -> 0 | I8: =COUNTIF('Coverage-Detail-ProJcl-2010'!H140:H141,"Q3") -> 0 | J8: =COUNTIF('Coverage-Detail-ProJcl-2010'!H140:H141,"Q4") -> 0 | K8: =SUM(G8:J8) -> 0 | L8: =COUNTIF('Coverage-Detail-ProJcl-2010'!D133:D141,"X") -> 5 | M8: =L8/E8*100 -> 71.428571
A9: MAP | B9: Pro/JCL | C9: Product Usage | D9: Claudie | E9: ='Coverage-Detail-ProJcl-2010'!A146 -> 1 | F9: ='Coverage-Detail-ProJcl-2010'!E146 -> 0 | G9: =COUNTIF('Coverage-Detail-ProJcl-2010'!H144:H145,"Q1") -> 0 | H9: =COUNTIF('Coverage-Detail-ProJcl-2010'!H144:H145,"Q2") -> 0 | I9: =COUNTIF('Coverage-Detail-ProJcl-2010'!H144:H145,"Q3") -> 0 | J9: =COUNTIF('Coverage-Detail-ProJcl-2010'!H144:H145,"Q4") -> 0 | K9: =SUM(G9:J9) -> 0 | L9: =COUNTIF('Coverage-Detail-ProJcl-2010'!D144:D145,"X") -> 0 | M9: =L9/E9*100 -> 0
A10: MAP | B10: Pro/JCL | C10: Reformat | D10: Claudie | E10: ='Coverage-Detail-ProJcl-2010'!A168 -> 20 | F10: ='Coverage-Detail-ProJcl-2010'!E168 -> 0 | G10: =COUNTIF('Coverage-Detail-ProJcl-2010'!H148:H167,"Q1") -> 1 | H10: =COUNTIF('Coverage-Detail-ProJcl-2010'!H148:H167,"Q2") -> 0 | I10: =COUNTIF('Coverage-Detail-ProJcl-2010'!H148:H167,"Q3") -> 0 | J10: =COUNTIF('Coverage-Detail-ProJcl-2010'!H148:H167,"Q4") -> 0 | K10: =SUM(G10:J10) -> 1 | L10: =COUNTIF('Coverage-Detail-ProJcl-2010'!D148:D167,"X") -> 16 | M10: =L10/E10*100 -> 80
A11: MAP | B11: Pro/JCL | C11: Remote Validation | D11: Claudie | E11: ='Coverage-Detail-ProJcl-2010'!A179 -> 8 | F11: ='Coverage-Detail-ProJcl-2010'!E179 -> 0 | G11: =COUNTIF('Coverage-Detail-ProJcl-2010'!H171:H178,"Q1") -> 2 | H11: =COUNTIF('Coverage-Detail-ProJcl-2010'!H171:H178,"Q2") -> 0 | I11: =COUNTIF('Coverage-Detail-ProJcl-2010'!H171:H178,"Q3") -> 0 | J11: =COUNTIF('Coverage-Detail-ProJcl-2010'!H171:H178,"Q4") -> 0 | K11: =SUM(G11:J11) -> 2 | L11: =COUNTIF('Coverage-Detail-ProJcl-2010'!D171:D178,"X") -> 8 | M11: =L11/E11*100 -> 100
A12: MAP | B12: Pro/JCL | C12: RTS | D12: Claudie | E12: =SUM('Coverage-Detail-ProJcl-2010'!A201,'Coverage-Detail-ProJcl-2010'!A231) -> 47 | F12: ='Coverage-Detail-ProJcl-2010'!E231 -> 0 | G12: =COUNTIF('Coverage-Detail-ProJcl-2010'!H181:H230,"Q1") -> 0 | H12: =COUNTIF('Coverage-Detail-ProJcl-2010'!H181:H230,"Q2") -> 0 | I12: =COUNTIF('Coverage-Detail-ProJcl-2010'!H181:H230,"Q3") -> 0 | J12: =COUNTIF('Coverage-Detail-ProJcl-2010'!H181:H230,"Q4") -> 0 | K12: =SUM(G12:J12) -> 0 | L12: =COUNTIF('Coverage-Detail-ProJcl-2010'!D181:D230,"X") -> 40 | M12: =L12/E12*100 -> 85.106383
A13: MAP | B13: Pro/JCL | C13: Scheduler | D13: Claudie | E13: ='Coverage-Detail-ProJcl-2010'!A260 -> 26 | F13: ='Coverage-Detail-ProJcl-2010'!E260 -> 0 | G13: =COUNTIF('Coverage-Detail-ProJcl-2010'!H234:H259,"Q1") -> 0 | H13: =COUNTIF('Coverage-Detail-ProJcl-2010'!H234:H259,"Q2") -> 0 | I13: =COUNTIF('Coverage-Detail-ProJcl-2010'!H234:H259,"Q3") -> 0 | J13: =COUNTIF('Coverage-Detail-ProJcl-2010'!H234:H259,"Q4") -> 0 | K13: =SUM(G13:J13) -> 0 | L13: =COUNTIF('Coverage-Detail-ProJcl-2010'!D234:D259,"X") -> 20 | M13: =L13/E13*100 -> 76.923077
A14: MAP | B14: Pro/JCL | C14: Selection Exit | D14: Claudie | E14: ='Coverage-Detail-ProJcl-2010'!A264 -> 1 | F14: ='Coverage-Detail-ProJcl-2010'!E264 -> 0 | G14: =COUNTIF('Coverage-Detail-ProJcl-2010'!H262:H263,"Q1") -> 0 | H14: =COUNTIF('Coverage-Detail-ProJcl-2010'!H262:H263,"Q2") -> 0 | I14: =COUNTIF('Coverage-Detail-ProJcl-2010'!H262:H263,"Q3") -> 0 | J14: =COUNTIF('Coverage-Detail-ProJcl-2010'!H262:H263,"Q4") -> 0 | K14: =SUM(G14:J14) -> 0 | L14: =COUNTIF('Coverage-Detail-ProJcl-2010'!D262:D263,"X") -> 1 | M14: =L14/E14*100 -> 100
A15: MAP | B15: Pro/JCL | C15: Selection List | D15: Claudie | E15: ='Coverage-Detail-ProJcl-2010'!A274 -> 7 | F15: ='Coverage-Detail-ProJcl-2010'!E274 -> 0 | G15: =COUNTIF('Coverage-Detail-ProJcl-2010'!H263:H273,"Q1") -> 0 | H15: =COUNTIF('Coverage-Detail-ProJcl-2010'!H263:H273,"Q2") -> 0 | I15: =COUNTIF('Coverage-Detail-ProJcl-2010'!H263:H273,"Q3") -> 0 | J15: =COUNTIF('Coverage-Detail-ProJcl-2010'!H263:H273,"Q4") -> 0 | K15: =SUM(G15:J15) -> 0 | L15: =COUNTIF('Coverage-Detail-ProJcl-2010'!D266:D272,"X") -> 6 | M15: =L15/E15*100 -> 85.714286
A16: MAP | B16: Pro/JCL | C16: Shared | D16: Claudie | E16: ='Coverage-Detail-ProJcl-2010'!A284 -> 7 | F16: ='Coverage-Detail-ProJcl-2010'!E284 -> 0 | G16: =COUNTIF('Coverage-Detail-ProJcl-2010'!H276:H283,"Q1") -> 6 | H16: =COUNTIF('Coverage-Detail-ProJcl-2010'!H276:H283,"Q2") -> 0 | I16: =COUNTIF('Coverage-Detail-ProJcl-2010'!H276:H283,"Q3") -> 0 | J16: =COUNTIF('Coverage-Detail-ProJcl-2010'!H276:H283,"Q4") -> 0 | K16: =SUM(G16:J16) -> 6 | L16: =COUNTIF('Coverage-Detail-ProJcl-2010'!D276:D282,"X") -> 6 | M16: =L16/E16*100 -> 85.714286
A17: MAP | B17: Pro/JCL | C17: STC | D17: Claudie | E17: ='Coverage-Detail-ProJcl-2010'!A288 -> 1 | F17: ='Coverage-Detail-ProJcl-2010'!E288 -> 0 | G17: =COUNTIF('Coverage-Detail-ProJcl-2010'!H286:H287,"Q1") -> 1 | H17: =COUNTIF('Coverage-Detail-ProJcl-2010'!H286:H287,"Q2") -> 0 | I17: =COUNTIF('Coverage-Detail-ProJcl-2010'!H286:H287,"Q3") -> 0 | J17: =COUNTIF('Coverage-Detail-ProJcl-2010'!H286:H287,"Q4") -> 0 | K17: =SUM(G17:J17) -> 1 | L17: =COUNTIF('Coverage-Detail-ProJcl-2010'!D286:D287,"X") -> 1 | M17: =L17/E17*100 -> 100
A18: MAP | B18: Pro/JCL | C18: System | D18: Claudie | E18: ='Coverage-Detail-ProJcl-2010'!A300 -> 8 | F18: ='Coverage-Detail-ProJcl-2010'!E300 -> 0 | G18: =COUNTIF('Coverage-Detail-ProJcl-2010'!H290:H299,"Q1") -> 1 | H18: =COUNTIF('Coverage-Detail-ProJcl-2010'!H290:H299,"Q2") -> 0 | I18: =COUNTIF('Coverage-Detail-ProJcl-2010'!H290:H299,"Q3") -> 0 | J18: =COUNTIF('Coverage-Detail-ProJcl-2010'!H290:H299,"Q4") -> 0 | K18: =SUM(G18:J18) -> 1 | L18: =COUNTIF('Coverage-Detail-ProJcl-2010'!D290:D299,"X") -> 5 | M18: =L18/E18*100 -> 62.5
A19: MAP | B19: Pro/JCL | C19: Validation | D19: Claudie | E19: =SUM('Coverage-Detail-ProJcl-2010'!A320,'Coverage-Detail-ProJcl-2010'!A343) -> 38 | F19: ='Coverage-Detail-ProJcl-2010'!E343 -> 0 | G19: =COUNTIF('Coverage-Detail-ProJcl-2010'!H302:H342,"Q1") -> 1 | H19: =COUNTIF('Coverage-Detail-ProJcl-2010'!H302:H342,"Q2") -> 0 | I19: =COUNTIF('Coverage-Detail-ProJcl-2010'!H302:H342,"Q3") -> 0 | J19: =COUNTIF('Coverage-Detail-ProJcl-2010'!H302:H342,"Q4") -> 0 | K19: =SUM(G19:J19) -> 1 | L19: =COUNTIF('Coverage-Detail-ProJcl-2010'!D302:D342,"X") -> 35 | M19: =L19/E19*100 -> 92.105263
A20: QTP | B20: Pro/JCL | C20: Customize | D20: Scott
A21: QTP | B21: Pro/JCL | C21: JCL Editor | D21: Scott
A22: QTP | B22: Pro/JCL | C22: JMP | D22: Scott
A23: QTP | B23: Pro/JCL | C23: Local Scan | D23: Scott
A24: QTP | B24: Pro/JCL | C24: Mainframe Scan | D24: Scott
C25: Summary | E25: =SUM(E2:E24) -> 285 | F25: =SUM(F2:F24) -> 0 | G25: =SUM(G2:G24) -> 21 | H25: =SUM(H2:H24) -> 0 | I25: =SUM(I2:I24) -> 0 | J25: =SUM(J2:J24) -> 0 | K25: =SUM(K2:K24) -> 21 | L25: =SUM(L2:L24) -> 253
A26: MAP | B26: INFOX | C26: A_NISSAN_263 | D26: Lisa | E26: ='Coverage-Detail-Infox-2010'!A9 -> 6 | F26: ='Coverage-Detail-Infox-2010'!E9 -> 0 | G26: =COUNTIF('Coverage-Detail-Infox-2010'!H3:H8,"Q1") -> 1 | H26: =COUNTIF('Coverage-Detail-Infox-2010'!H3:H8,"Q2") -> 0 | I26: =COUNTIF('Coverage-Detail-Infox-2010'!H3:H8,"Q3") -> 0 | J26: =COUNTIF('Coverage-Detail-Infox-2010'!H3:H8,"Q4") -> 0 | K26: =SUM(G26:J26) -> 1 | L26: =SUM(G26:J26) -> 1 | M26: =L26/E26*100 -> 16.666667
B27: INFOX | C27: QUERY1 | D27: Lisa | E27: ='Coverage-Detail-Infox-2010'!A21 -> 10 | F27: ='Coverage-Detail-Infox-2010'!E21 -> 0 | G27: =COUNTIF('Coverage-Detail-Infox-2010'!H11:H20,"Q1") -> 0 | H27: =COUNTIF('Coverage-Detail-Infox-2010'!H11:H20,"Q2") -> 0 | I27: =COUNTIF('Coverage-Detail-Infox-2010'!H11:H20,"Q3") -> 0 | J27: =COUNTIF('Coverage-Detail-Infox-2010'!H11:H20,"Q4") -> 0 | K27: =SUM(G27:J27) -> 0 | L27: =SUM(G27:J27) -> 0 | M27: =L27/E27*100 -> 0
B28: INFOX | C28: REPORTS | D28: Lisa | E28: ='Coverage-Detail-Infox-2010'!A45 -> 22 | F28: ='Coverage-Detail-Infox-2010'!E45 -> 0 | G28: =COUNTIF('Coverage-Detail-Infox-2010'!H23:H44,"Q1") -> 0 | H28: =COUNTIF('Coverage-Detail-Infox-2010'!H23:H44,"Q2") -> 0 | I28: =COUNTIF('Coverage-Detail-Infox-2010'!H23:H44,"Q3") -> 0 | J28: =COUNTIF('Coverage-Detail-Infox-2010'!H23:H44,"Q4") -> 0 | K28: =SUM(G28:J28) -> 0 | L28: =SUM(G28:J28) -> 0 | M28: =L28/E28*100 -> 0
B29: INFOX | C29: SETUP1 | D29: Lisa | E29: ='Coverage-Detail-Infox-2010'!A67 -> 20 | F29: ='Coverage-Detail-Infox-2010'!E67 -> 0 | G29: =COUNTIF('Coverage-Detail-Infox-2010'!H47:H66,"Q1") -> 0 | H29: =COUNTIF('Coverage-Detail-Infox-2010'!H47:H66,"Q2") -> 0 | I29: =COUNTIF('Coverage-Detail-Infox-2010'!H47:H66,"Q3") -> 0 | J29: =COUNTIF('Coverage-Detail-Infox-2010'!H47:H66,"Q4") -> 0 | K29: =SUM(G29:J29) -> 0 | L29: =SUM(G29:J29) -> 0 | M29: =L29/E29*100 -> 0
B30: INFOX | C30: UPDATE1 | D30: Lisa | E30: ='Coverage-Detail-Infox-2010'!A81 -> 12 | F30: ='Coverage-Detail-Infox-2010'!E81 -> 0 | G30: =COUNTIF('Coverage-Detail-Infox-2010'!H69:H80,"Q1") -> 0 | H30: =COUNTIF('Coverage-Detail-Infox-2010'!H69:H80,"Q2") -> 0 | I30: =COUNTIF('Coverage-Detail-Infox-2010'!H69:H80,"Q3") -> 0 | J30: =COUNTIF('Coverage-Detail-Infox-2010'!H69:H80,"Q4") -> 0 | K30: =SUM(G30:J30) -> 0 | L30: =SUM(G30:J30) -> 0 | M30: =L30/E30*100 -> 0
B31: INFOX | C31: XREF_CICSGROUP1 | D31: Lisa | E31: ='Coverage-Detail-Infox-2010'!A85 -> 2 | F31: ='Coverage-Detail-Infox-2010'!E85 -> 0 | G31: =COUNTIF('Coverage-Detail-Infox-2010'!H83:H84,"Q1") -> 0 | H31: =COUNTIF('Coverage-Detail-Infox-2010'!H83:H84,"Q2") -> 0 | I31: =COUNTIF('Coverage-Detail-Infox-2010'!H83:H84,"Q3") -> 0 | J31: =COUNTIF('Coverage-Detail-Infox-2010'!H83:H84,"Q4") -> 0 | K31: =SUM(G31:J31) -> 0 | L31: =SUM(G31:J31) -> 0 | M31: =L31/E31*100 -> 0
B32: INFOX | C32: XREF_CICSTRANSACTION1 | D32: Lisa | E32: ='Coverage-Detail-Infox-2010'!A91 -> 4 | F32: ='Coverage-Detail-Infox-2010'!E91 -> 0 | G32: =COUNTIF('Coverage-Detail-Infox-2010'!H87:H90,"Q1") -> 0 | H32: =COUNTIF('Coverage-Detail-Infox-2010'!H87:H90,"Q2") -> 0 | I32: =COUNTIF('Coverage-Detail-Infox-2010'!H87:H90,"Q3") -> 0 | J32: =COUNTIF('Coverage-Detail-Infox-2010'!H87:H90,"Q4") -> 0 | K32: =SUM(G32:J32) -> 0 | L32: =SUM(G32:J32) -> 0 | M32: =L32/E32*100 -> 0
B33: INFOX | C33: XREF_DB2COLLECTIONID1 | D33: Lisa | E33: ='Coverage-Detail-Infox-2010'!A96 -> 2 | F33: ='Coverage-Detail-Infox-2010'!E96 -> 1 | G33: =COUNTIF('Coverage-Detail-Infox-2010'!H93:H95,"Q1") -> 0 | H33: =COUNTIF('Coverage-Detail-Infox-2010'!H93:H95,"Q2") -> 3 | I33: =COUNTIF('Coverage-Detail-Infox-2010'!H93:H95,"Q3") -> 0 | J33: =COUNTIF('Coverage-Detail-Infox-2010'!H93:H95,"Q4") -> 0 | K33: =SUM(G33:J33) -> 3 | L33: =SUM(G33:J33) -> 3 | M33: =L33/E33*100 -> 150
B34: INFOX | C34: XREF_DB2PACKAGE1 | D34: Lisa | E34: ='Coverage-Detail-Infox-2010'!A101 -> 3 | F34: ='Coverage-Detail-Infox-2010'!E101 -> 0 | G34: =COUNTIF('Coverage-Detail-Infox-2010'!H98:H100,"Q1") -> 0 | H34: =COUNTIF('Coverage-Detail-Infox-2010'!H98:H100,"Q2") -> 2 | I34: =COUNTIF('Coverage-Detail-Infox-2010'!H98:H100,"Q3") -> 0 | J34: =COUNTIF('Coverage-Detail-Infox-2010'!H98:H100,"Q4") -> 0 | K34: =SUM(G34:J34) -> 2 | L34: =SUM(G34:J34) -> 2 | M34: =L34/E34*100 -> 66.666667
B35: INFOX | C35: XREF_DB2PLAN1 | D35: Lisa | E35: ='Coverage-Detail-Infox-2010'!A105 -> 2 | F35: ='Coverage-Detail-Infox-2010'!E105 -> 0 | G35: =COUNTIF('Coverage-Detail-Infox-2010'!H103:H104,"Q1") -> 0 | H35: =COUNTIF('Coverage-Detail-Infox-2010'!H103:H104,"Q2") -> 1 | I35: =COUNTIF('Coverage-Detail-Infox-2010'!H103:H104,"Q3") -> 0 | J35: =COUNTIF('Coverage-Detail-Infox-2010'!H103:H104,"Q4") -> 0 | K35: =SUM(G35:J35) -> 1 | L35: =SUM(G35:J35) -> 1 | M35: =L35/E35*100 -> 50
B36: INFOX | C36: XREF_DB2TABLE1 | D36: Lisa | E36: ='Coverage-Detail-Infox-2010'!A110 -> 3 | F36: ='Coverage-Detail-Infox-2010'!E110 -> 0 | G36: =COUNTIF('Coverage-Detail-Infox-2010'!H107:H109,"Q1") -> 0 | H36: =COUNTIF('Coverage-Detail-Infox-2010'!H107:H109,"Q2") -> 2 | I36: =COUNTIF('Coverage-Detail-Infox-2010'!H107:H109,"Q3") -> 0 | J36: =COUNTIF('Coverage-Detail-Infox-2010'!H107:H109,"Q4") -> 0 | K36: =SUM(G36:J36) -> 2 | L36: =SUM(G36:J36) -> 2 | M36: =L36/E36*100 -> 66.666667
B37: INFOX | C37: XREF_DSNAME1 | D37: Lisa | E37: ='Coverage-Detail-Infox-2010'!A117 -> 4 | F37: ='Coverage-Detail-Infox-2010'!E117 -> 0 | G37: =COUNTIF('Coverage-Detail-Infox-2010'!H112:H116,"Q1") -> 0 | H37: =COUNTIF('Coverage-Detail-Infox-2010'!H112:H116,"Q2") -> 1 | I37: =COUNTIF('Coverage-Detail-Infox-2010'!H112:H116,"Q3") -> 0 | J37: =COUNTIF('Coverage-Detail-Infox-2010'!H112:H116,"Q4") -> 0 | K37: =SUM(G37:J37) -> 1 | L37: =SUM(G37:J37) -> 1 | M37: =L37/E37*100 -> 25
B38: INFOX | C38: ADMINISTRATOR | D38: Claudie | E38: ='Coverage-Detail-Infox-2010'!A131 -> 12 | F38: ='Coverage-Detail-Infox-2010'!E131 -> 0 | G38: =COUNTIF('Coverage-Detail-Infox-2010'!H119:H124,"Q1") -> 3 | H38: =COUNTIF('Coverage-Detail-Infox-2010'!H119:H130,"Q2") -> 7 | I38: =COUNTIF('Coverage-Detail-Infox-2010'!H119:H124,"Q3") -> 0 | J38: =COUNTIF('Coverage-Detail-Infox-2010'!H119:H124,"Q4") -> 0 | K38: =SUM(G38:J38) -> 10 | L38: =SUM(G38:J38) -> 10 | M38: =L38/E38*100 -> 83.333333
B39: INFOX | C39: XREF_JOB1 | D39: Claudie | E39: ='Coverage-Detail-Infox-2010'!A143 -> 10 | F39: ='Coverage-Detail-Infox-2010'!E143 -> 0 | G39: =COUNTIF('Coverage-Detail-Infox-2010'!H142:H1135,"Q1") -> 0 | H39: =COUNTIF('Coverage-Detail-Infox-2010'!H133:H142,"Q2") -> 9 | I39: =COUNTIF('Coverage-Detail-Infox-2010'!H133:H142,"Q3") -> 0 | J39: =COUNTIF('Coverage-Detail-Infox-2010'!H133:H142,"Q4") -> 0 | K39: =SUM(G39:J39) -> 9 | L39: =SUM(G39:J39) -> 9 | M39: =L39/E39*100 -> 90
B40: INFOX | C40: FOLDERS | D40: Claudie | E40: ='Coverage-Detail-Infox-2010'!A147 -> 2 | F40: ='Coverage-Detail-Infox-2010'!E147 -> 0 | G40: =COUNTIF('Coverage-Detail-Infox-2010'!H145:H146,"Q1") -> 0 | H40: =COUNTIF('Coverage-Detail-Infox-2010'!H145:H146,"Q2") -> 2 | I40: =COUNTIF('Coverage-Detail-Infox-2010'!H145:H146,"Q3") -> 0 | J40: =COUNTIF('Coverage-Detail-Infox-2010'!H145:H146,"Q4") -> 0 | K40: =SUM(G40:J40) -> 2 | L40: =SUM(G40:J40) -> 2 | M40: =L40/E40*100 -> 100
...

Sheet Coverage-Detail-ProJcl-2010
D1: Converted | E1: New | K1: Code | L1: Script
A2: Total for Suite | C2: WinRunner Scripts | D2: to MAP | E2: Script | F2: Date | G2: Analyst | H2: Quarter 2010 | I2: Analyst/Qtr | J2: Comments | K2: Review | L2: P/F/I | M2: Date | N2: Analyst | O2: Notes
B4: ADMIN1:
C5: PD1B006 | D5: X | F5: 39822 | G5: LisaC
C6: PH35055 | F6: 39846 | G6: LisaC | J6: need function to handle parameter tables
C7: PH43055 | D7: X | F7: 40046 | G7: cjm | J7: need function to check cursor position
C8: PH15034 | D8: X | F8: 40044 | G8: LisaC | J8: waiting for 'presskey' function & function to handle popup panel w/ no scroll field
C9: PH49014 | D9: X | F9: 40045 | G9: cjm
C10: PH48002 | D10: X | F10: 40046 | G10: cjm
C11: PH16071 | D11: X | F11: 40049 | G11: cjm
A12: =COUNTA(C5:C11) -> 7 | E12: =COUNTIF(E5:E11,"Y") -> 0
B14: HELP1:
C15: HELP_ADMINISTRATION | D15: X | F15: 39937 | G15: cjm | J15: D0JHDIA3.txt has 2 panel ID (the first panel and the superimposed popup panelid)
C16: HELP_JMP_SETTINGS | D16: X | F16: 40049 | G16: cjm
C17: HELP_MAINMENU | D17: X | F17: 39938 | G17: cjm
C18: HELP_REFORMATTER | D18: X | F18: 39953 | G18: cjm
C19: HELP_REFORMATTER_STATEMENTS | D19: X | F19: 39953 | G19: cjm
C20: HELP_RTS_SETTINGS | D20: X | F20: 39938 | G20: cjm
A21: =COUNTA(C15:C21) -> 6
B23: HELP2:
C24: P12738 | D24: X | F24: 39961 | G24: cjm
C25: P13219 | D25: X | F25: 39961 | G25: cjm
C26: PC11012 | D26: X | F26: 39961 | G26: cjm | J26: capture Reformat DD help panel D0SHREF3 has extra blank pages at the bottom.
C27: PH22125 | D27: X | F27: 39965 | G27: cjm
C28: PH25112 | D28: X | F28: 39965 | G28: cjm
C29: PH2C051 | D29: X | F29: 39965 | G29: cjm
C30: PH43053 | D30: X | F30: 39966 | G30: cjm | J30: Test for copyright failed opening Impact ticket: 683536
C31: P685586 | D31: X | F31: 40126 | G31: cjm | J31: New testcase PR290
A32: =COUNTA(C24:C31) -> 8 | E32: =COUNTIF(E15:E31,"Y") -> 0
B33: JJ1
C34: P10927 | D34: X | F34: 39870 | G34: cjm
C35: P11135 | D35: X | F35: 39842 | G35: LisaC
C36: P11573 | D36: X | F36: 39869 | G36: cjm
C37: P12455 | D37: X | F37: 39869 | G37: cjm
C38: P12479 | D38: X | F38: 39870 | G38: cjm
C39: P12783 | D39: X | F39: 39869 | G39: cjm
C40: P13394 | D40: X | F40: 40149 | G40: cjm
C41: PC24008 | D41: X | F41: 39871 | G41: cjm
C42: PH11081 | D42: X | F42: 40150 | G42: cjm
C43: PH11083 | D43: X | F43: 39871 | G43: cjm
...

Sheet Coverage-Detail-Infox-2010
A1: Suite Totals | B1: Suite | C1: Test Case Document | D1: Converted to MAP | E1: New Scripts | F1: Date | G1: Analyst/Qtr | H1: Quarter | I1: Estimated Time | J1: Actual Time | K1: Lisa Est. Time | L1: Claudie Est. Time | M1: Comments | N1: Comments
A2: Lisa | B2: A_NISSAN_263
C3: IC53007 | D3: Y | G3: LisaQ1 | H3: Q1 | I3: 4
C4: IH54039 | I4: 4 | M4: scott
C5: IC55006 | I5: 4
C6: IC53008 | I6: 4
C7: IC55010 | I7: 4
C8: IH54029 | I8: 4 | K8: 24
A9: =COUNTA(C3:C8) -> 6 | E9: =COUNTIF(E3:E8,"Y") -> 0
A10: Lisa | B10: QUERY1
C11: IH4B026 | D11: in progress | I11: 2
C12: I12602 | I12: 2
C13: I12628 | I13: 2
C14: I12757 | I14: 2
C15: IH11020 | I15: 2
C16: IH1A166 | I16: 2
C17: IH55035 | I17: 2
C18: IU3A008 | I18: 2
C19: IM92355 | I19: 2
C20: PIQRY001 | I20: 2 | K20: 20
A21: =COUNTA(C10:C20) -> 10
A22: Lisa | B22: REPORTS | E22: =COUNTIF(E11:E21,"Y") -> 0
C23: IH54031 | I23: 2
C24: IC11025 | I24: 2
C25: IC18007 | I25: 2
C26: IC1C005 | I26: 2
C27: IC27001 | I27: 2
C28: ID12008 | I28: 2
C29: ID12010 | I29: 2
C30: IH12106 | I30: 2
C31: IH1C035 | I31: 2
C32: IH1C071 | I32: 2
C33: IH23036 | I33: 2
C34: IH48031 | I34: 2
... C42: IH55054 | I42: 2
C43: IM92493 | I43: 2 | K43: 44
C44: IM92538 | I44: 2
A45: =COUNTA(C23:C44) -> 22 | E45: =COUNTIF(E23:E44,"Y") -> 0
A46: Lisa | B46: SETUP1
C47: IH48072 | I47: 2
...

Sheet Automation FY2010
A1: Product | B1: Version | C1: Platform(s) | D1: Type | E1: Created by | F1: # of TC as of 12/31/09 | G1: # of TS as of 12/31/09 | H1: # of TC as of 12/31/10 | I1: # of TS as of 12/31/10 | J1: New TC this FY | K1: New TS this FY
A2: Pro/JCL - ISPF | B2: 2.9 | C2: Z/OS | D2: MAP | E2: QA | F2: ='FY 2009 Coverage'!E36 -> 260 | G2: ='FY 2009 Coverage'!J36 -> 245 | J2: ='FY2010 Coverage'!F25 -> 0 | K2: ='FY2010 Coverage'!F25 -> 0
A3: Info/Xe - ISPF | B3: 2.9 | C3: Z/OS | D3: MAP | E3: QA | J3: ='FY2010 Coverage'!F50 -> 2 | K3: ='FY2010 Coverage'!F50 -> 2
A4: Info/Xe - Windows Client | B4: 2.9 | C4: W32; W64 | D4: QTP | E4: QA
E5: Totals | F5: =SUM(F2:F3) -> 260 | G5: =SUM(G2:G3) -> 245 | H5: =SUM(H2:H3) -> 0 | I5: =SUM(I2:I3) -> 0 | J5: =SUM(J2:J3) -> 2 | K5: =SUM(K2:K3) -> 2
E6: Increase | K6: =(+G5-#REF!)/#REF! -> #REF!
A10: Notes:
A11: Original 276 Pro/JCLTestCases were WinRunner; coverted to MAP scripts
A12: Original 175 Info/Xe TestCases were WinRunner; coverted to MAP scripts

Sheet Automation FY09
A1: Product | B1: Version | C1: Platform(s) | D1: Type | E1: Created by | F1: # of TC as of 12/31/09 | G1: # of TS as of 12/31/09 | H1: New TC this FY | I1: New TS this FY
A2: Pro/JCL - ISPF | B2: 2.9 | C2: Z/OS | D2: MAP | E2: QA | F2: ='FY 2009 Coverage'!E36 -> 260 | G2: ='FY 2009 Coverage'!J36 -> 245 | H2: 4 | I2: 248
A3: Info/Xe - ISPF | B3: 2.9 | C3: Z/OS | D3: MAP | E3: QA
A4: Info/Xe - Windows Client | B4: 2.9 | C4: W32; W64 | D4: QTP | E4: QA
E5: Totals | F5: =SUM(F2:F3) -> 260 | G5: =SUM(G2:G3) -> 245 | H5: =SUM(H2:H3) -> 4 | I5: =SUM(I2:I3) -> 248
E6: Increase | I6: =(+G5-#REF!)/#REF! -> #REF!
A9: Notes:
A10: Original 276 Pro/JCLTestCases were WinRunner; coverted to MAP scripts
A11: Original 175 Info/Xe TestCases were WinRunner; coverted to MAP scripts

Sheet FY09 Totals
A1: Quarter Totals
B2: Q1 | D2: Q2 | F2: Q3 | H2: Q4 | J2: FY TCtal
A3: AuTCmation Type | B3: TC | C3: TS | D3: TC | E3: TS | F3: TC | G3: TS | H3: TC | I3: TS | J3: TC | K3: TS
A4: MAP - Pro/JCL | H4: ='FY 2009 Coverage'!E27 -> 260 | I4: ='FY 2009 Coverage'!J27 -> 245 | J4: =SUM(B4,D4,F4,H4) -> 260 | K4: =SUM(C4,E4,G4,I4) -> 245
A5: MAP - Infox | J5: =SUM(B5,D5,F5,H5) -> 0 | K5: =SUM(C5,E5,G5,I5) -> 0
J6: =SUM(B6,D6,F6,H6) -> 0 | K6: =SUM(C6,E6,G6,I6) -> 0
A7: TCtals | B7: =SUM(B4:B6) -> 0 | C7: =SUM(C4:C6) -> 0 | D7: =SUM(D4:D6) -> 0 | E7: =SUM(E4:E6) -> 0 | F7: =SUM(F4:F6) -> 0 | G7: =SUM(G4:G6) -> 0 | H7: =SUM(H4:H6) -> 260 | I7: =SUM(I4:I6) -> 245 | ... K7: =SUM(K4:K6) -> 245
A12: Totals for each AuTCmation Developer
B13: Q1 | D13: Q2 | F13: Q3 | H13: Q4 | J13: Developer TCtal
A14: Developer | B14: TC | C14: TS | D14: TC | E14: TS | F14: TC | G14: TS | H14: TC | I14: TS | J14: TC | K14: TS
A15: Claudie | H15: ='FY 2009 Coverage'!E36 -> 260 | I15: 248 | J15: =SUM(B15,D15,F15,H15) -> 260 | K15: =SUM(C15,E15,G15,I15,) -> 248
A16: Lisa | J16: =SUM(B16,D16,F16,H16) -> 0 | K16: =SUM(C16,E16,G16,I16,) -> 0
A17: Scott | J17: 0 | K17: 0
A18: TCtals | B18: =SUM(B15:B16) -> 0 | C18: =SUM(C15:C16) -> 0 | D18: =SUM(D15:D16) -> 0 | E18: =SUM(E15:E16) -> 0 | F18: =SUM(F15:F16) -> 0 | G18: =SUM(G15:G16) -> 0 | H18: =SUM(H15:H16) -> 260 | I18: =SUM(I15:I16) -> 248 | ... K18: =SUM(K15:K16) -> 248

Sheet FY 2009 Coverage
A1: Automation Type | B1: Product | C1: Area Covered | D1: Owner | E1: Test Cases | F1: Scripts Q1 | G1: Scripts Q2 | H1: Scripts Q3 | I1: Scripts Q4 | J1: Total Scripts | K1: % complt
A2: MAP | B2: Pro/JCL | C2: Admin | D2: Claudie | E2: ='Coverage-Detail-ProJcl-2010'!A12 -> 7 | J2: =COUNTIF('Coverage-Detail-ProJcl-2010'!D5:D11,"X") -> 6 | K2: =J2/E2*100 -> 85.714286
A3: MAP | B3: Pro/JCL | C3: Help | D3: Claudie | E3: =SUM('Coverage-Detail-ProJcl-2010'!A32,'Coverage-Detail-ProJcl-2010'!A21) -> 14 | J3: =COUNTIF('Coverage-Detail-ProJcl-2010'!D15:D31,"X") -> 14 | K3: =J3/E3*100 -> 100
A4: MAP | B4: Pro/JCL | C4: JJ | D4: Claudie | E4: =SUM('Coverage-Detail-ProJcl-2010'!A52,'Coverage-Detail-ProJcl-2010'!A87) -> 50 | J4: =COUNTIF('Coverage-Detail-ProJcl-2010'!D34:D86,"X") -> 49 | K4: =J4/E4*100 -> 98
A5: MAP | B5: Pro/JCL | C5: JJDirect | D5: Claudie | E5: ='Coverage-Detail-ProJcl-2010'!A105 -> 15 | J5: =COUNTIF('Coverage-Detail-ProJcl-2010'!D90:D104,"X") -> 13 | K5: =J5/E5*100 -> 86.666667
A6: MAP | B6: Pro/JCL | C6: JJScan | D6: Claudie | E6: ='Coverage-Detail-ProJcl-2010'!A111 -> 3 | J6: =COUNTIF('Coverage-Detail-ProJcl-2010'!D108:D110,"X") -> 3 | K6: =J6/E6*100 -> 100
A7: MAP | B7: Pro/JCL | C7: JMP | D7: Claudie | E7: ='Coverage-Detail-ProJcl-2010'!A131 -> 0 | J7: =COUNTIF('Coverage-Detail-ProJcl-2010'!D114:D130,"X") -> 17 | K7: =J7/E7*100 -> #DIV/0!
A8: MAP | B8: Pro/JCL | C8: MISC | D8: Claudie | E8: ='Coverage-Detail-ProJcl-2010'!A142 -> 7 | J8: =COUNTIF('Coverage-Detail-ProJcl-2010'!D133:D141,"X") -> 5 | K8: =J8/E8*100 -> 71.428571
A9: MAP | B9: Pro/JCL | C9: Product Usage | D9: Claudie | E9: ='Coverage-Detail-ProJcl-2010'!A146 -> 1 | J9: =COUNTIF('Coverage-Detail-ProJcl-2010'!D144:D145,"X") -> 0 | K9: =J9/E9*100 -> 0
A10: MAP | B10: Pro/JCL | C10: Reformat | D10: Claudie | E10: ='Coverage-Detail-ProJcl-2010'!A168 -> 20 | J10: =COUNTIF('Coverage-Detail-ProJcl-2010'!D148:D167,"X") -> 16 | K10: =J10/E10*100 -> 80
A11: MAP | B11: Pro/JCL | C11: Remote Validation | D11: Claudie | E11: ='Coverage-Detail-ProJcl-2010'!A179 -> 8 | J11: =COUNTIF('Coverage-Detail-ProJcl-2010'!D171:D178,"X") -> 8 | K11: =J11/E11*100 -> 100
A12: MAP | B12: Pro/JCL | C12: RTS | D12: Claudie | E12: =SUM('Coverage-Detail-ProJcl-2010'!A201,'Coverage-Detail-ProJcl-2010'!A231) -> 47 | J12: =COUNTIF('Coverage-Detail-ProJcl-2010'!D181:D230,"X") -> 40 | K12: =J12/E12*100 -> 85.106383
A13: MAP | B13: Pro/JCL | C13: Scheduler | D13: Claudie | E13: ='Coverage-Detail-ProJcl-2010'!A260 -> 26 | J13: =COUNTIF('Coverage-Detail-ProJcl-2010'!D234:D259,"X") -> 20 | K13: =J13/E13*100 -> 76.923077
A14: MAP | B14: Pro/JCL | C14: Selection Exit | D14: Claudie | E14: ='Coverage-Detail-ProJcl-2010'!A264 -> 1 | J14: =COUNTIF('Coverage-Detail-ProJcl-2010'!D262:D263,"X") -> 1 | K14: =J14/E14*100 -> 100
A15: MAP | B15: Pro/JCL | C15: Selection List | D15: Claudie | E15: ='Coverage-Detail-ProJcl-2010'!A274 -> 7 | J15: =COUNTIF('Coverage-Detail-ProJcl-2010'!D266:D272,"X") -> 6 | K15: =J15/E15*100 -> 85.714286
A16: MAP | B16: Pro/JCL | C16: Shared | D16: Claudie | E16: ='Coverage-Detail-ProJcl-2010'!A284 -> 7 | J16: =COUNTIF('Coverage-Detail-ProJcl-2010'!D276:D282,"X") -> 6 | K16: =J16/E16*100 -> 85.714286
A17: MAP | B17: Pro/JCL | C17: STC | D17: Claudie | E17: ='Coverage-Detail-ProJcl-2010'!A288 -> 1 | J17: =COUNTIF('Coverage-Detail-ProJcl-2010'!D286:D287,"X") -> 1 | K17: =J17/E17*100 -> 100
A18: MAP | B18: Pro/JCL | C18: System | D18: Claudie | E18: ='Coverage-Detail-ProJcl-2010'!A300 -> 8 | J18: =COUNTIF('Coverage-Detail-ProJcl-2010'!D290:D299,"X") -> 5 | K18: =J18/E18*100 -> 62.5
A19: MAP | B19: Pro/JCL | C19: Validation | D19: Claudie | E19: =SUM('Coverage-Detail-ProJcl-2010'!A320,'Coverage-Detail-ProJcl-2010'!A343) -> 38 | J19: =COUNTIF('Coverage-Detail-ProJcl-2010'!D302:D342,"X") -> 35 | K19: =J19/E19*100 -> 92.105263
A20: QTP | B20: Pro/JCL | C20: Customize | D20: Scott
A21: QTP | B21: Pro/JCL | C21: JCL Editor | D21: Scott
A22: QTP | B22: Pro/JCL | C22: JMP | D22: Scott
A23: QTP | B23: Pro/JCL | C23: Local Scan | D23: Scott
A24: QTP | B24: Pro/JCL | C24: Mainframe Scan | D24: Scott
A25: QTP | B25: Pro/JCL | C25: Quick Scan | D25: Scott
B26: Pro/JCL | C26: Map Infrastructure/new functions | D26: Scott
C27: Summary | E27: =SUM(E2:E26) -> 260 | F27: =SUM(F2:F26) -> 0 | G27: =SUM(G2:G26) -> 0 | H27: =SUM(H2:H26) -> 0 | I27: =SUM(I2:I26) -> 0 | J27: =SUM(J2:J26) -> 245 | K27: =J27/E27*100 -> 94.230769
A29: MAP | B29: INFOX | D29: Scott
C31: Summary | E31: =SUM(E29:E30) -> 0 | F31: =SUM(F29:F30) -> 0 | G31: =SUM(G29:G30) -> 0 | H31: =SUM(H29:H30) -> 0 | I31: =SUM(I29:I30) -> 0 | J31: =SUM(J29:J30) -> 0
C36: Total Automation | E36: =SUM(E27+E31) -> 260 | F36: =SUM(F27+F31) -> 0 | G36: =SUM(G27+G31) -> 0 | H36: =SUM(H27+H31) -> 0 | I36: =SUM(I27+I31) -> 0 | J36: =SUM(J27+J31) -> 245
B38: Note: the Coverage-Detail report will be updated with a date routine to pull stats on a quarterly basis.
